Workbook

Sheet Legend
A1: GST Scrutiny Tool – Rule Matrix
A3: Sheet | B3: Purpose
A4: Rule Matrix | B4: One row per check: legal ref, data sources, logic, threshold, severity, exposure basis, action. Yellow columns (Status, Exposure ₹, Remarks) are for the user/system to fill.
A5: Data Sources | B5: Inputs the tool must ingest, with key fields.
A6: Summary | B6: Auto counts by module/severity/status and total exposure (formulas).
A7: Sec 73-74 Classifier | B7: Per flagged issue: enter Rule ID, FY, tax, fraud indicators, payment stage, interest dates → auto section (73/74/74A), SCN & order deadlines, limitation status, penalty, interest, s.128A flag.
A8: Client Master | B8: Client list: name, GSTIN, industry (drop-down) and Y/N flags (Exports, Imports, SEZ, E-invoice, Multi-GSTIN). Auto-counts applicable rules.
A9: Client Checklist | B9: Select client → auto-filtered list of applicable checks (industry + flags).
A10: Applicability | B10: Rule × industry matrix (Y/N, editable) + client flag required per rule. Change a Y/N here and every client's checklist updates.
A11: Validation Log | B11: What was verified/corrected on 21-Sep-2026, with sources. Read before using the matrix.
A12: Limitation Inputs | B12: Annual return due dates, COVID-extended s.73 deadlines, interest rate, as-of date (editable, blue).
A14: Status values | B14: Pending / Pass / Fail / N.A. (drop-down)
A15: Severity | B15: High = direct tax exposure likely; Med = exposure possible/conditional; Low = procedural
... A18: Example row | B18: Rule Matrix row 2 (B-01) filled with sample Status 'Fail', Exposure ₹1,25,000 to show format.

Sheet Validation Log
A1: # | B1: Area | C1: Provision checked | D1: Result | E1: Finding / correction applied | F1: Primary source
A2: 1 | B2: Demand | C2: s.73/74 vs s.74A | D2: Verified | E2: FY ≤ 2023-24 → s.73/74; FY 2024-25 onwards → s.74A (in force 01.11.2024). SCN 42 months from AR due date; order 12 months (+6). | F2: Finance (No.2) Act 2024
A3: 2 | B3: Demand | C3: s.74A de minimis | D3: Corrected (added) | E3: No SCN where tax < ₹1,000 per FY – new rule K + classifier flag. | F3: s.74A(1) proviso
A4: 3 | B4: Demand | C4: Reduced-penalty windows | D4: Verified | E4: 30 days (s.73/74) vs 60 days (s.74A). | F4: s.74A(5),(8)
A5: 4 | B5: Demand | C5: 168A COVID extensions | D5: Flag – sub judice | E5: Madras HC (Tata Play, 12.06.2025) struck down 9/2023 & 56/2023; Telangana HC (Brunda Infra) upheld; SC SLP (HCC-SEW-MEIL-AAG JV) – check final outcome before relying. | F5: Notfn 9/2023, 56/2023
A6: 5 | B6: Demand | C6: Suppression standard | D6: Added | E6: SC: Uniworth Textiles, Pushpam Pharmaceuticals, Continental Foundation – intent must be pleaded and proved. | F6: SC judgments
A7: 6 | B7: ITC | C7: s.17(5)(d) plant & machinery | D7: Corrected | E7: Earlier matrix tagged FA 2025 amendment to cl.(c); correct clause is (d) with Explanation 2, retro 01.07.2017, overriding Safari Retreats. | F7: Finance Act 2025, s.119 of Bill
A8: 7 | B8: CN | C8: s.34(2) proviso | D8: Verified + dated | E8: Recipient-reversal condition effective 01.10.2025 (Notfn 16/2025-CT), enforced via IMS. | F8: Finance Act 2025
A9: 8 | B9: CN | C9: s.15(3)(b) post-sale discount | D9: Updated | E9: FA 2026 substitution (no pre-agreement) enacted but awaiting notification – old conditions apply until notified. Circ 251/08/2025: no recipient reversal on financial CNs. | F9: FA 2026; Circ 251/08/2025
A10: 9 | B10: CN | C10: s.16(4) debit note date | D10: Corrected | E10: Amendment is FA 2020 w.e.f. 01.01.2021 (not FA 2022). | F10: Finance Act 2020
A11: 10 | B11: POS | C11: Intermediary s.13(8)(b) | D11: Updated | E11: Omitted by FA 2026 s.157 w.e.f. 30.03.2026 (prospective). Legacy periods remain exposed; inbound foreign intermediary now RCM. | F11: Finance Act 2026
A12: 11 | B12: Rates | C12: Hotel & restaurant | D12: Updated | E12: Rooms ≤ ₹7,500: 5% w/o ITC; > ₹7,500: 18% (22.09.2025). Restaurant at specified premises 18% with ITC (Notfn 05/2025 w.e.f. 01.04.2025). | F12: Notfn 05/2025, 15/2025-CT(R)
A13: 12 | B13: Rates | C13: GTA | D13: Updated | E13: 12% FCM replaced by 18% with ITC from 22.09.2025; Annexure V by 31 March (not 15 March). | F13: Notfn 15/2025-CT(R)
... A23: 22 | B23: ITC | C23: Rule 37A / s.16(2)(c) | D23: Added defence | E23: Suncraft Energy line – bona fide recipient; verify post-2022 s.16(2)(aa) position. | F23: Cal HC; SC SLP dismissed
A25: Checked on 21-Sep-2026 against CBIC notifications/circulars and reported judgments via web sources. Re-verify before filing any reply; law and SC outcomes may have moved.

Sheet Client Master
A1: Client Name | B1: GSTIN | C1: Industry | D1: Exports | E1: Imports | F1: SEZ Supplies | G1: E-invoice | H1: Multi-GSTIN | I1: Applicable Rules (auto)
A2: Sample Developers LLP | B2: 27AAAAA0000A1Z5 | C2: Real Estate Developer | D2: N | E2: N | F2: N | G2: Y | H2: N | I2: =IF(C2="","",IFERROR(SUMPRODUCT((INDEX(Applicability!$E$2:$O$142,0,MATCH(C2,Applicability!$E$1:$O$1,0))="Y")*((Applicability!$D$2:$D$142="")+(Applicability!$D$2:$D$142="Exports")*(D2="Y")+(Applicability!$D$2:$D$142="Imports")*(E2="Y")+(Applicability!$D$2:$D$142="SEZ Supplies")*(F2="Y")+(Applicability!$D$2:$D$142="E-invoice")*(G2="Y")+(Applicability!$D$2:$D$142="Multi-GSTIN")*(H2="Y"))),"Check industry")) -> 96
A3: Sample Traders | B3: 27BBBBB0000B1Z5 | C3: Trader / Retailer | D3: N | E3: Y | F3: N | G3: N | H3: N | I3: =IF(C3="","",IFERROR(SUMPRODUCT((INDEX(Applicability!$E$2:$O$142,0,MATCH(C3,Applicability!$E$1:$O$1,0))="Y")*((Applicability!$D$2:$D$142="")+(Applicability!$D$2:$D$142="Exports")*(D3="Y")+(Applicability!$D$2:$D$142="Imports")*(E3="Y")+(Applicability!$D$2:$D$142="SEZ Supplies")*(F3="Y")+(Applicability!$D$2:$D$142="E-invoice")*(G3="Y")+(Applicability!$D$2:$D$142="Multi-GSTIN")*(H3="Y"))),"Check industry")) -> 96
A4: Sample Co-op Bank Ltd | B4: 27CCCCC0000C1Z5 | C4: Bank / NBFC / Co-op Bank | D4: N | E4: N | F4: N | G4: Y | H4: Y | I4: =IF(C4="","",IFERROR(SUMPRODUCT((INDEX(Applicability!$E$2:$O$142,0,MATCH(C4,Applicability!$E$1:$O$1,0))="Y")*((Applicability!$D$2:$D$142="")+(Applicability!$D$2:$D$142="Exports")*(D4="Y")+(Applicability!$D$2:$D$142="Imports")*(E4="Y")+(Applicability!$D$2:$D$142="SEZ Supplies")*(F4="Y")+(Applicability!$D$2:$D$142="E-invoice")*(G4="Y")+(Applicability!$D$2:$D$142="Multi-GSTIN")*(H4="Y"))),"Check industry")) -> 93
A5: Sample Restaurant | B5: 27DDDDD0000D1Z5 | C5: Hotel / Restaurant | D5: N | E5: N | F5: N | G5: N | H5: N | I5: =IF(C5="","",IFERROR(SUMPRODUCT((INDEX(Applicability!$E$2:$O$142,0,MATCH(C5,Applicability!$E$1:$O$1,0))="Y")*((Applicability!$D$2:$D$142="")+(Applicability!$D$2:$D$142="Exports")*(D5="Y")+(Applicability!$D$2:$D$142="Imports")*(E5="Y")+(Applicability!$D$2:$D$142="SEZ Supplies")*(F5="Y")+(Applicability!$D$2:$D$142="E-invoice")*(G5="Y")+(Applicability!$D$2:$D$142="Multi-GSTIN")*(H5="Y"))),"Check industry")) -> 91
A6: Sample IT Services Pvt Ltd | B6: 27EEEEE0000E1Z5 | C6: Service Provider | D6: Y | E6: Y | F6: Y | G6: Y | H6: N | I6: =IF(C6="","",IFERROR(SUMPRODUCT((INDEX(Applicability!$E$2:$O$142,0,MATCH(C6,Applicability!$E$1:$O$1,0))="Y")*((Applicability!$D$2:$D$142="")+(Applicability!$D$2:$D$142="Exports")*(D6="Y")+(Applicability!$D$2:$D$142="Imports")*(E6="Y")+(Applicability!$D$2:$D$142="SEZ Supplies")*(F6="Y")+(Applicability!$D$2:$D$142="E-invoice")*(G6="Y")+(Applicability!$D$2:$D$142="Multi-GSTIN")*(H6="Y"))),"Check industry")) -> 97
I7: =IF(C7="","",IFERROR(SUMPRODUCT((INDEX(Applicability!$E$2:$O$142,0,MATCH(C7,Applicability!$E$1:$O$1,0))="Y")*((Applicability!$D$2:$D$142="")+(Applicability!$D$2:$D$142="Exports")*(D7="Y")+(Applicability!$D$2:$D$142="Imports")*(E7="Y")+(Applicability!$D$2:$D$142="SEZ Supplies")*(F7="Y")+(Applicability!$D$2:$D$142="E-invoice")*(G7="Y")+(Applicability!$D$2:$D$142="Multi-GSTIN")*(H7="Y"))),"Check industry"))
I8: =IF(C8="","",IFERROR(SUMPRODUCT((INDEX(Applicability!$E$2:$O$142,0,MATCH(C8,Applicability!$E$1:$O$1,0))="Y")*((Applicability!$D$2:$D$142="")+(Applicability!$D$2:$D$142="Exports")*(D8="Y")+(Applicability!$D$2:$D$142="Imports")*(E8="Y")+(Applicability!$D$2:$D$142="SEZ Supplies")*(F8="Y")+(Applicability!$D$2:$D$142="E-invoice")*(G8="Y")+(Applicability!$D$2:$D$142="Multi-GSTIN")*(H8="Y"))),"Check industry"))
I9: =IF(C9="","",IFERROR(SUMPRODUCT((INDEX(Applicability!$E$2:$O$142,0,MATCH(C9,Applicability!$E$1:$O$1,0))="Y")*((Applicability!$D$2:$D$142="")+(Applicability!$D$2:$D$142="Exports")*(D9="Y")+(Applicability!$D$2:$D$142="Imports")*(E9="Y")+(Applicability!$D$2:$D$142="SEZ Supplies")*(F9="Y")+(Applicability!$D$2:$D$142="E-invoice")*(G9="Y")+(Applicability!$D$2:$D$142="Multi-GSTIN")*(H9="Y"))),"Check industry"))
I10: =IF(C10="","",IFERROR(SUMPRODUCT((INDEX(Applicability!$E$2:$O$142,0,MATCH(C10,Applicability!$E$1:$O$1,0))="Y")*((Applicability!$D$2:$D$142="")+(Applicability!$D$2:$D$142="Exports")*(D10="Y")+(Applicability!$D$2:$D$142="Imports")*(E10="Y")+(Applicability!$D$2:$D$142="SEZ Supplies")*(F10="Y")+(Applicability!$D$2:$D$142="E-invoice")*(G10="Y")+(Applicability!$D$2:$D$142="Multi-GSTIN")*(H10="Y"))),"Check industry"))
I11: =IF(C11="","",IFERROR(SUMPRODUCT((INDEX(Applicability!$E$2:$O$142,0,MATCH(C11,Applicability!$E$1:$O$1,0))="Y")*((Applicability!$D$2:$D$142="")+(Applicability!$D$2:$D$142="Exports")*(D11="Y")+(Applicability!$D$2:$D$142="Imports")*(E11="Y")+(Applicability!$D$2:$D$142="SEZ Supplies")*(F11="Y")+(Applicability!$D$2:$D$142="E-invoice")*(G11="Y")+(Applicability!$D$2:$D$142="Multi-GSTIN")*(H11="Y"))),"Check industry"))
I12: =IF(C12="","",IFERROR(SUMPRODUCT((INDEX(Applicability!$E$2:$O$142,0,MATCH(C12,Applicability!$E$1:$O$1,0))="Y")*((Applicability!$D$2:$D$142="")+(Applicability!$D$2:$D$142="Exports")*(D12="Y")+(Applicability!$D$2:$D$142="Imports")*(E12="Y")+(Applicability!$D$2:$D$142="SEZ Supplies")*(F12="Y")+(Applicability!$D$2:$D$142="E-invoice")*(G12="Y")+(Applicability!$D$2:$D$142="Multi-GSTIN")*(H12="Y"))),"Check industry"))
I13: =IF(C13="","",IFERROR(SUMPRODUCT((INDEX(Applicability!$E$2:$O$142,0,MATCH(C13,Applicability!$E$1:$O$1,0))="Y")*((Applicability!$D$2:$D$142="")+(Applicability!$D$2:$D$142="Exports")*(D13="Y")+(Applicability!$D$2:$D$142="Imports")*(E13="Y")+(Applicability!$D$2:$D$142="SEZ Supplies")*(F13="Y")+(Applicability!$D$2:$D$142="E-invoice")*(G13="Y")+(Applicability!$D$2:$D$142="Multi-GSTIN")*(H13="Y"))),"Check industry"))
I14: =IF(C14="","",IFERROR(SUMPRODUCT((INDEX(Applicability!$E$2:$O$142,0,MATCH(C14,Applicability!$E$1:$O$1,0))="Y")*((Applicability!$D$2:$D$142="")+(Applicability!$D$2:$D$142="Exports")*(D14="Y")+(Applicability!$D$2:$D$142="Imports")*(E14="Y")+(Applicability!$D$2:$D$142="SEZ Supplies")*(F14="Y")+(Applicability!$D$2:$D$142="E-invoice")*(G14="Y")+(Applicability!$D$2:$D$142="Multi-GSTIN")*(H14="Y"))),"Check industry"))
I15: =IF(C15="","",IFERROR(SUMPRODUCT((INDEX(Applicability!$E$2:$O$142,0,MATCH(C15,Applicability!$E$1:$O$1,0))="Y")*((Applicability!$D$2:$D$142="")+(Applicability!$D$2:$D$142="Exports")*(D15="Y")+(Applicability!$D$2:$D$142="Imports")*(E15="Y")+(Applicability!$D$2:$D$142="SEZ Supplies")*(F15="Y")+(Applicability!$D$2:$D$142="E-invoice")*(G15="Y")+(Applicability!$D$2:$D$142="Multi-GSTIN")*(H15="Y"))),"Check industry"))
I16: =IF(C16="","",IFERROR(SUMPRODUCT((INDEX(Applicability!$E$2:$O$142,0,MATCH(C16,Applicability!$E$1:$O$1,0))="Y")*((Applicability!$D$2:$D$142="")+(Applicability!$D$2:$D$142="Exports")*(D16="Y")+(Applicability!$D$2:$D$142="Imports")*(E16="Y")+(Applicability!$D$2:$D$142="SEZ Supplies")*(F16="Y")+(Applicability!$D$2:$D$142="E-invoice")*(G16="Y")+(Applicability!$D$2:$D$142="Multi-GSTIN")*(H16="Y"))),"Check industry"))
I17: =IF(C17="","",IFERROR(SUMPRODUCT((INDEX(Applicability!$E$2:$O$142,0,MATCH(C17,Applicability!$E$1:$O$1,0))="Y")*((Applicability!$D$2:$D$142="")+(Applicability!$D$2:$D$142="Exports")*(D17="Y")+(Applicability!$D$2:$D$142="Imports")*(E17="Y")+(Applicability!$D$2:$D$142="SEZ Supplies")*(F17="Y")+(Applicability!$D$2:$D$142="E-invoice")*(G17="Y")+(Applicability!$D$2:$D$142="Multi-GSTIN")*(H17="Y"))),"Check industry"))
I18: =IF(C18="","",IFERROR(SUMPRODUCT((INDEX(Applicability!$E$2:$O$142,0,MATCH(C18,Applicability!$E$1:$O$1,0))="Y")*((Applicability!$D$2:$D$142="")+(Applicability!$D$2:$D$142="Exports")*(D18="Y")+(Applicability!$D$2:$D$142="Imports")*(E18="Y")+(Applicability!$D$2:$D$142="SEZ Supplies")*(F18="Y")+(Applicability!$D$2:$D$142="E-invoice")*(G18="Y")+(Applicability!$D$2:$D$142="Multi-GSTIN")*(H18="Y"))),"Check industry"))
... I61: =IF(C61="","",IFERROR(SUMPRODUCT((INDEX(Applicability!$E$2:$O$142,0,MATCH(C61,Applicability!$E$1:$O$1,0))="Y")*((Applicability!$D$2:$D$142="")+(Applicability!$D$2:$D$142="Exports")*(D61="Y")+(Applicability!$D$2:$D$142="Imports")*(E61="Y")+(Applicability!$D$2:$D$142="SEZ Supplies")*(F61="Y")+(Applicability!$D$2:$D$142="E-invoice")*(G61="Y")+(Applicability!$D$2:$D$142="Multi-GSTIN")*(H61="Y"))),"Check industry"))

Sheet Client Checklist
A1: Select Client | B1: Sample Developers LLP | D1: Pick a client in B1 – list below refreshes. For working papers, copy-paste values into a client tab (statuses here don't move with the list).
A2: Industry | B2: =IFERROR(INDEX('Client Master'!$C$2:$C$61,MATCH($B$1,'Client Master'!$A$2:$A$61,0)),"") -> Real Estate Developer
A3: Client flags | B3: Exports | C3: Imports | D3: SEZ Supplies | E3: E-invoice | F3: Multi-GSTIN
B4: =IFERROR(INDEX('Client Master'!$D$2:$D$61,MATCH($B$1,'Client Master'!$A$2:$A$61,0)),"N") -> N | C4: =IFERROR(INDEX('Client Master'!$E$2:$E$61,MATCH($B$1,'Client Master'!$A$2:$A$61,0)),"N") -> N | D4: =IFERROR(INDEX('Client Master'!$F$2:$F$61,MATCH($B$1,'Client Master'!$A$2:$A$61,0)),"N") -> N | E4: =IFERROR(INDEX('Client Master'!$G$2:$G$61,MATCH($B$1,'Client Master'!$A$2:$A$61,0)),"N") -> Y | F4: =IFERROR(INDEX('Client Master'!$H$2:$H$61,MATCH($B$1,'Client Master'!$A$2:$A$61,0)),"N") -> N
A5: Applicable rules | B5: =SUM(AA8:AA148) -> 96 | Z5: =IFERROR(MATCH($B$2,Applicability!$E$1:$O$1,0),0) -> 1
A7: Sr | B7: Rule ID | C7: Module | D7: Check | E7: Legal Reference | F7: Logic / Test | G7: Threshold | H7: Severity | I7: Action | Z7: Helper: Rule | AA7: Applies | AB7: Seq
A8: =IF(1>$B$5,"",1) -> 1 | B8: =IF(A8="","",INDEX($Z$8:$Z$148,MATCH(A8,$AB$8:$AB$148,0))) -> A-01 | C8: =IF(B8="","",INDEX('Rule Matrix'!$B$2:$B$142,MATCH(B8,'Rule Matrix'!$A$2:$A$142,0))) -> A. Data Integrity | D8: =IF(B8="","",INDEX('Rule Matrix'!$C$2:$C$142,MATCH(B8,'Rule Matrix'!$A$2:$A$142,0))) -> GSTIN master validation | E8: =IF(B8="","",INDEX('Rule Matrix'!$D$2:$D$142,MATCH(B8,'Rule Matrix'!$A$2:$A$142,0))) -> Rule 10A/21A | F8: =IF(B8="","",INDEX('Rule Matrix'!$F$2:$F$142,MATCH(B8,'Rule Matrix'!$A$2:$A$142,0))) -> Check each vendor/customer GSTIN active on invoice date; flag cancelled (incl. retrospective), suspended, composition | G8: =IF(B8="","",INDEX('Rule Matrix'!$G$2:$G$142,MATCH(B8,'Rule Matrix'!$A$2:$A$142,0))) -> Any mismatch | H8: =IF(B8="","",INDEX('Rule Matrix'!$H$2:$H$142,MATCH(B8,'Rule Matrix'!$A$2:$A$142,0))) -> High | I8: =IF(B8="","",INDEX('Rule Matrix'!$J$2:$J$142,MATCH(B8,'Rule Matrix'!$A$2:$A$142,0))) -> Reverse ITC; obtain vendor clarification | Z8: =Applicability!A2 -> A-01 | AA8: =IF($Z$5=0,0,IF(AND(INDEX(Applicability!$E$2:$O$2,1,$Z$5)="Y",OR(Applicability!$D$2="",IFERROR(INDEX($B$4:$F$4,MATCH(Applicability!$D$2,$B$3:$F$3,0)),"N")="Y")),1,0)) -> 1 | AB8: =IF(AA8=1,SUM(AA$8:AA8),"") -> 1
A9: =IF(2>$B$5,"",2) -> 2 | B9: =IF(A9="","",INDEX($Z$8:$Z$148,MATCH(A9,$AB$8:$AB$148,0))) -> A-02 | C9: =IF(B9="","",INDEX('Rule Matrix'!$B$2:$B$142,MATCH(B9,'Rule Matrix'!$A$2:$A$142,0))) -> A. Data Integrity | D9: =IF(B9="","",INDEX('Rule Matrix'!$C$2:$C$142,MATCH(B9,'Rule Matrix'!$A$2:$A$142,0))) -> Period & return filing completeness | E9: =IF(B9="","",INDEX('Rule Matrix'!$D$2:$D$142,MATCH(B9,'Rule Matrix'!$A$2:$A$142,0))) -> s.37/39/44 | F9: =IF(B9="","",INDEX('Rule Matrix'!$F$2:$F$142,MATCH(B9,'Rule Matrix'!$A$2:$A$142,0))) -> All GSTR-1/3B/9/9C filed for all periods; compute delay days | G9: =IF(B9="","",INDEX('Rule Matrix'!$G$2:$G$142,MATCH(B9,'Rule Matrix'!$A$2:$A$142,0))) -> Any non-filing | H9: =IF(B9="","",INDEX('Rule Matrix'!$H$2:$H$142,MATCH(B9,'Rule Matrix'!$A$2:$A$142,0))) -> Med | I9: =IF(B9="","",INDEX('Rule Matrix'!$J$2:$J$142,MATCH(B9,'Rule Matrix'!$A$2:$A$142,0))) -> File pending; pay late fee | Z9: =Applicability!A3 -> A-02 | AA9: =IF($Z$5=0,0,IF(AND(INDEX(Applicability!$E$3:$O$3,1,$Z$5)="Y",OR(Applicability!$D$3="",IFERROR(INDEX($B$4:$F$4,MATCH(Applicability!$D$3,$B$3:$F$3,0)),"N")="Y")),1,0)) -> 1 | AB9: =IF(AA9=1,SUM(AA$8:AA9),"") -> 2
A10: =IF(3>$B$5,"",3) -> 3 | B10: =IF(A10="","",INDEX($Z$8:$Z$148,MATCH(A10,$AB$8:$AB$148,0))) -> A-03 | C10: =IF(B10="","",INDEX('Rule Matrix'!$B$2:$B$142,MATCH(B10,'Rule Matrix'!$A$2:$A$142,0))) -> A. Data Integrity | D10: =IF(B10="","",INDEX('Rule Matrix'!$C$2:$C$142,MATCH(B10,'Rule Matrix'!$A$2:$A$142,0))) -> Books vs return data completeness | E10: =IF(B10="","",INDEX('Rule Matrix'!$D$2:$D$142,MATCH(B10,'Rule Matrix'!$A$2:$A$142,0))) -> — | F10: =IF(B10="","",INDEX('Rule Matrix'!$F$2:$F$142,MATCH(B10,'Rule Matrix'!$A$2:$A$142,0))) -> Sum of registers = GL control accounts; all GSTINs of PAN covered | G10: =IF(B10="","",INDEX('Rule Matrix'!$G$2:$G$142,MATCH(B10,'Rule Matrix'!$A$2:$A$142,0))) -> Diff > ₹1,000 | H10: =IF(B10="","",INDEX('Rule Matrix'!$H$2:$H$142,MATCH(B10,'Rule Matrix'!$A$2:$A$142,0))) -> Med | I10: =IF(B10="","",INDEX('Rule Matrix'!$J$2:$J$142,MATCH(B10,'Rule Matrix'!$A$2:$A$142,0))) -> Reconcile registers to GL | Z10: =Applicability!A4 -> A-03 | AA10: =IF($Z$5=0,0,IF(AND(INDEX(Applicability!$E$4:$O$4,1,$Z$5)="Y",OR(Applicability!$D$4="",IFERROR(INDEX($B$4:$F$4,MATCH(Applicability!$D$4,$B$3:$F$3,0)),"N")="Y")),1,0)) -> 1 | AB10: =IF(AA10=1,SUM(AA$8:AA10),"") -> 3
A11: =IF(4>$B$5,"",4) -> 4 | B11: =IF(A11="","",INDEX($Z$8:$Z$148,MATCH(A11,$AB$8:$AB$148,0))) -> B-01 | C11: =IF(B11="","",INDEX('Rule Matrix'!$B$2:$B$142,MATCH(B11,'Rule Matrix'!$A$2:$A$142,0))) -> B. ITC Eligibility (s.16) | D11: =IF(B11="","",INDEX('Rule Matrix'!$C$2:$C$142,MATCH(B11,'Rule Matrix'!$A$2:$A$142,0))) -> ITC claimed vs GSTR-2B | E11: =IF(B11="","",INDEX('Rule Matrix'!$D$2:$D$142,MATCH(B11,'Rule Matrix'!$A$2:$A$142,0))) -> s.16(2)(aa), Rule 36(4) | F11: =IF(B11="","",INDEX('Rule Matrix'!$F$2:$F$142,MATCH(B11,'Rule Matrix'!$A$2:$A$142,0))) -> Line-level match: GSTIN+Inv No+Date+Taxable+Tax; ITC in 3B > 2B → excess | G11: =IF(B11="","",INDEX('Rule Matrix'!$G$2:$G$142,MATCH(B11,'Rule Matrix'!$A$2:$A$142,0))) -> Diff > ₹1,000/month or > 1% | H11: =IF(B11="","",INDEX('Rule Matrix'!$H$2:$H$142,MATCH(B11,'Rule Matrix'!$A$2:$A$142,0))) -> High | I11: =IF(B11="","",INDEX('Rule Matrix'!$J$2:$J$142,MATCH(B11,'Rule Matrix'!$A$2:$A$142,0))) -> Reverse via DRC-03; respond to DRC-01C (Rule 88D) | Z11: =Applicability!A5 -> B-01 | AA11: =IF($Z$5=0,0,IF(AND(INDEX(Applicability!$E$5:$O$5,1,$Z$5)="Y",OR(Applicability!$D$5="",IFERROR(INDEX($B$4:$F$4,MATCH(Applicability!$D$5,$B$3:$F$3,0)),"N")="Y")),1,0)) -> 1 | AB11: =IF(AA11=1,SUM(AA$8:AA11),"") -> 4
A12: =IF(5>$B$5,"",5) -> 5 | B12: =IF(A12="","",INDEX($Z$8:$Z$148,MATCH(A12,$AB$8:$AB$148,0))) -> B-02 | C12: =IF(B12="","",INDEX('Rule Matrix'!$B$2:$B$142,MATCH(B12,'Rule Matrix'!$A$2:$A$142,0))) -> B. ITC Eligibility (s.16) | D12: =IF(B12="","",INDEX('Rule Matrix'!$C$2:$C$142,MATCH(B12,'Rule Matrix'!$A$2:$A$142,0))) -> ITC in books but not in 2B | E12: =IF(B12="","",INDEX('Rule Matrix'!$D$2:$D$142,MATCH(B12,'Rule Matrix'!$A$2:$A$142,0))) -> s.16(2)(aa) | F12: =IF(B12="","",INDEX('Rule Matrix'!$F$2:$F$142,MATCH(B12,'Rule Matrix'!$A$2:$A$142,0))) -> Invoices in books absent in 2B/IMS | G12: =IF(B12="","",INDEX('Rule Matrix'!$G$2:$G$142,MATCH(B12,'Rule Matrix'!$A$2:$A$142,0))) -> Any | H12: =IF(B12="","",INDEX('Rule Matrix'!$H$2:$H$142,MATCH(B12,'Rule Matrix'!$A$2:$A$142,0))) -> Med | I12: =IF(B12="","",INDEX('Rule Matrix'!$J$2:$J$142,MATCH(B12,'Rule Matrix'!$A$2:$A$142,0))) -> Vendor follow-up; defer claim | Z12: =Applicability!A6 -> B-02 | AA12: =IF($Z$5=0,0,IF(AND(INDEX(Applicability!$E$6:$O$6,1,$Z$5)="Y",OR(Applicability!$D$6="",IFERROR(INDEX($B$4:$F$4,MATCH(Applicability!$D$6,$B$3:$F$3,0)),"N")="Y")),1,0)) -> 1 | AB12: =IF(AA12=1,SUM(AA$8:AA12),"") -> 5
A13: =IF(6>$B$5,"",6) -> 6 | B13: =IF(A13="","",INDEX($Z$8:$Z$148,MATCH(A13,$AB$8:$AB$148,0))) -> B-03 | C13: =IF(B13="","",INDEX('Rule Matrix'!$B$2:$B$142,MATCH(B13,'Rule Matrix'!$A$2:$A$142,0))) -> B. ITC Eligibility (s.16) | D13: =IF(B13="","",INDEX('Rule Matrix'!$C$2:$C$142,MATCH(B13,'Rule Matrix'!$A$2:$A$142,0))) -> Receipt of goods/services | E13: =IF(B13="","",INDEX('Rule Matrix'!$D$2:$D$142,MATCH(B13,'Rule Matrix'!$A$2:$A$142,0))) -> s.16(2)(b) | F13: =IF(B13="","",INDEX('Rule Matrix'!$F$2:$F$142,MATCH(B13,'Rule Matrix'!$A$2:$A$142,0))) -> Invoice without GRN/EWB for goods; bill-to-ship-to documentation | G13: =IF(B13="","",INDEX('Rule Matrix'!$G$2:$G$142,MATCH(B13,'Rule Matrix'!$A$2:$A$142,0))) -> Any | H13: =IF(B13="","",INDEX('Rule Matrix'!$H$2:$H$142,MATCH(B13,'Rule Matrix'!$A$2:$A$142,0))) -> High | I13: =IF(B13="","",INDEX('Rule Matrix'!$J$2:$J$142,MATCH(B13,'Rule Matrix'!$A$2:$A$142,0))) -> Obtain proof of receipt | Z13: =Applicability!A7 -> B-03 | AA13: =IF($Z$5=0,0,IF(AND(INDEX(Applicability!$E$7:$O$7,1,$Z$5)="Y",OR(Applicability!$D$7="",IFERROR(INDEX($B$4:$F$4,MATCH(Applicability!$D$7,$B$3:$F$3,0)),"N")="Y")),1,0)) -> 1 | AB13: =IF(AA13=1,SUM(AA$8:AA13),"") -> 6
A14: =IF(7>$B$5,"",7) -> 7 | B14: =IF(A14="","",INDEX($Z$8:$Z$148,MATCH(A14,$AB$8:$AB$148,0))) -> B-04 | C14: =IF(B14="","",INDEX('Rule Matrix'!$B$2:$B$142,MATCH(B14,'Rule Matrix'!$A$2:$A$142,0))) -> B. ITC Eligibility (s.16) | D14: =IF(B14="","",INDEX('Rule Matrix'!$C$2:$C$142,MATCH(B14,'Rule Matrix'!$A$2:$A$142,0))) -> Supplier tax payment (Rule 37A) | E14: =IF(B14="","",INDEX('Rule Matrix'!$D$2:$D$142,MATCH(B14,'Rule Matrix'!$A$2:$A$142,0))) -> s.16(2)(c), Rule 37A; Suncraft Energy (Cal HC; SC dismissed SLP, Dec 2023) | F14: =IF(B14="","",INDEX('Rule Matrix'!$F$2:$F$142,MATCH(B14,'Rule Matrix'!$A$2:$A$142,0))) -> Vendor 3B not filed by 30 Sept of next FY → reverse by 30 Nov. Defence: ITC cannot be denied to bona fide buyer solely for supplier default without first proceeding against supplier | G14: =IF(B14="","",INDEX('Rule Matrix'!$G$2:$G$142,MATCH(B14,'Rule Matrix'!$A$2:$A$142,0))) -> Any | H14: =IF(B14="","",INDEX('Rule Matrix'!$H$2:$H$142,MATCH(B14,'Rule Matrix'!$A$2:$A$142,0))) -> High | I14: =IF(B14="","",INDEX('Rule Matrix'!$J$2:$J$142,MATCH(B14,'Rule Matrix'!$A$2:$A$142,0))) -> Reverse by 30 Nov; reclaim once vendor files | Z14: =Applicability!A8 -> B-04 | AA14: =IF($Z$5=0,0,IF(AND(INDEX(Applicability!$E$8:$O$8,1,$Z$5)="Y",OR(Applicability!$D$8="",IFERROR(INDEX($B$4:$F$4,MATCH(Applicability!$D$8,$B$3:$F$3,0)),"N")="Y")),1,0)) -> 1 | AB14: =IF(AA14=1,SUM(AA$8:AA14),"") -> 7
A15: =IF(8>$B$5,"",8) -> 8 | B15: =IF(A15="","",INDEX($Z$8:$Z$148,MATCH(A15,$AB$8:$AB$148,0))) -> B-05 | C15: =IF(B15="","",INDEX('Rule Matrix'!$B$2:$B$142,MATCH(B15,'Rule Matrix'!$A$2:$A$142,0))) -> B. ITC Eligibility (s.16) | D15: =IF(B15="","",INDEX('Rule Matrix'!$C$2:$C$142,MATCH(B15,'Rule Matrix'!$A$2:$A$142,0))) -> Payment within 180 days | E15: =IF(B15="","",INDEX('Rule Matrix'!$D$2:$D$142,MATCH(B15,'Rule Matrix'!$A$2:$A$142,0))) -> Rule 37, s.16(2) 2nd proviso | F15: =IF(B15="","",INDEX('Rule Matrix'!$F$2:$F$142,MATCH(B15,'Rule Matrix'!$A$2:$A$142,0))) -> Unpaid value > 180 days from invoice date (excl. RCM, deemed supply) | G15: =IF(B15="","",INDEX('Rule Matrix'!$G$2:$G$142,MATCH(B15,'Rule Matrix'!$A$2:$A$142,0))) -> Any | H15: =IF(B15="","",INDEX('Rule Matrix'!$H$2:$H$142,MATCH(B15,'Rule Matrix'!$A$2:$A$142,0))) -> High | I15: =IF(B15="","",INDEX('Rule Matrix'!$J$2:$J$142,MATCH(B15,'Rule Matrix'!$A$2:$A$142,0))) -> Reverse in 3B; reclaim on payment | Z15: =Applicability!A9 -> B-05 | AA15: =IF($Z$5=0,0,IF(AND(INDEX(Applicability!$E$9:$O$9,1,$Z$5)="Y",OR(Applicability!$D$9="",IFERROR(INDEX($B$4:$F$4,MATCH(Applicability!$D$9,$B$3:$F$3,0)),"N")="Y")),1,0)) -> 1 | AB15: =IF(AA15=1,SUM(AA$8:AA15),"") -> 8
A16: =IF(9>$B$5,"",9) -> 9 | B16: =IF(A16="","",INDEX($Z$8:$Z$148,MATCH(A16,$AB$8:$AB$148,0))) -> B-06 | C16: =IF(B16="","",INDEX('Rule Matrix'!$B$2:$B$142,MATCH(B16,'Rule Matrix'!$A$2:$A$142,0))) -> B. ITC Eligibility (s.16) | D16: =IF(B16="","",INDEX('Rule Matrix'!$C$2:$C$142,MATCH(B16,'Rule Matrix'!$A$2:$A$142,0))) -> Depreciation on tax component | E16: =IF(B16="","",INDEX('Rule Matrix'!$D$2:$D$142,MATCH(B16,'Rule Matrix'!$A$2:$A$142,0))) -> s.16(3) | F16: =IF(B16="","",INDEX('Rule Matrix'!$F$2:$F$142,MATCH(B16,'Rule Matrix'!$A$2:$A$142,0))) -> Capital goods where ITC claimed AND GST capitalised in cost | G16: =IF(B16="","",INDEX('Rule Matrix'!$G$2:$G$142,MATCH(B16,'Rule Matrix'!$A$2:$A$142,0))) -> Any | H16: =IF(B16="","",INDEX('Rule Matrix'!$H$2:$H$142,MATCH(B16,'Rule Matrix'!$A$2:$A$142,0))) -> High | I16: =IF(B16="","",INDEX('Rule Matrix'!$J$2:$J$142,MATCH(B16,'Rule Matrix'!$A$2:$A$142,0))) -> Reverse ITC or de-capitalise | Z16: =Applicability!A10 -> B-06 | AA16: =IF($Z$5=0,0,IF(AND(INDEX(Applicability!$E$10:$O$10,1,$Z$5)="Y",OR(Applicability!$D$10="",IFERROR(INDEX($B$4:$F$4,MATCH(Applicability!$D$10,$B$3:$F$3,0)),"N")="Y")),1,0)) -> 1 | AB16: =IF(AA16=1,SUM(AA$8:AA16),"") -> 9
A17: =IF(10>$B$5,"",10) -> 10 | B17: =IF(A17="","",INDEX($Z$8:$Z$148,MATCH(A17,$AB$8:$AB$148,0))) -> B-07 | C17: =IF(B17="","",INDEX('Rule Matrix'!$B$2:$B$142,MATCH(B17,'Rule Matrix'!$A$2:$A$142,0))) -> B. ITC Eligibility (s.16) | D17: =IF(B17="","",INDEX('Rule Matrix'!$C$2:$C$142,MATCH(B17,'Rule Matrix'!$A$2:$A$142,0))) -> Time limit for ITC | E17: =IF(B17="","",INDEX('Rule Matrix'!$D$2:$D$142,MATCH(B17,'Rule Matrix'!$A$2:$A$142,0))) -> s.16(4), 16(5), 16(6) | F17: =IF(B17="","",INDEX('Rule Matrix'!$F$2:$F$142,MATCH(B17,'Rule Matrix'!$A$2:$A$142,0))) -> Claimed after earlier of 30 Nov next FY / annual return date; DN date used for DN | G17: =IF(B17="","",INDEX('Rule Matrix'!$G$2:$G$142,MATCH(B17,'Rule Matrix'!$A$2:$A$142,0))) -> Any | H17: =IF(B17="","",INDEX('Rule Matrix'!$H$2:$H$142,MATCH(B17,'Rule Matrix'!$A$2:$A$142,0))) -> High | I17: =IF(B17="","",INDEX('Rule Matrix'!$J$2:$J$142,MATCH(B17,'Rule Matrix'!$A$2:$A$142,0))) -> Reverse; check 16(5)/(6) relaxation | Z17: =Applicability!A11 -> B-07 | AA17: =IF($Z$5=0,0,IF(AND(INDEX(Applicability!$E$11:$O$11,1,$Z$5)="Y",OR(Applicability!$D$11="",IFERROR(INDEX($B$4:$F$4,MATCH(Applicability!$D$11,$B$3:$F$3,0)),"N")="Y")),1,0)) -> 1 | AB17: =IF(AA17=1,SUM(AA$8:AA17),"") -> 10
A18: =IF(11>$B$5,"",11) -> 11 | B18: =IF(A18="","",INDEX($Z$8:$Z$148,MATCH(A18,$AB$8:$AB$148,0))) -> B-08 | C18: =IF(B18="","",INDEX('Rule Matrix'!$B$2:$B$142,MATCH(B18,'Rule Matrix'!$A$2:$A$142,0))) -> B. ITC Eligibility (s.16) | D18: =IF(B18="","",INDEX('Rule Matrix'!$C$2:$C$142,MATCH(B18,'Rule Matrix'!$A$2:$A$142,0))) -> Duplicate ITC | E18: =IF(B18="","",INDEX('Rule Matrix'!$D$2:$D$142,MATCH(B18,'Rule Matrix'!$A$2:$A$142,0))) -> s.16 | F18: =IF(B18="","",INDEX('Rule Matrix'!$F$2:$F$142,MATCH(B18,'Rule Matrix'!$A$2:$A$142,0))) -> Same GSTIN+Inv No claimed twice / across GSTINs / periods | G18: =IF(B18="","",INDEX('Rule Matrix'!$G$2:$G$142,MATCH(B18,'Rule Matrix'!$A$2:$A$142,0))) -> Any | H18: =IF(B18="","",INDEX('Rule Matrix'!$H$2:$H$142,MATCH(B18,'Rule Matrix'!$A$2:$A$142,0))) -> High | I18: =IF(B18="","",INDEX('Rule Matrix'!$J$2:$J$142,MATCH(B18,'Rule Matrix'!$A$2:$A$142,0))) -> Reverse | Z18: =Applicability!A12 -> B-08 | AA18: =IF($Z$5=0,0,IF(AND(INDEX(Applicability!$E$12:$O$12,1,$Z$5)="Y",OR(Applicability!$D$12="",IFERROR(INDEX($B$4:$F$4,MATCH(Applicability!$D$12,$B$3:$F$3,0)),"N")="Y")),1,0)) -> 1 | AB18: =IF(AA18=1,SUM(AA$8:AA18),"") -> 11
A19: =IF(12>$B$5,"",12) -> 12 | B19: =IF(A19="","",INDEX($Z$8:$Z$148,MATCH(A19,$AB$8:$AB$148,0))) -> B-10 | C19: =IF(B19="","",INDEX('Rule Matrix'!$B$2:$B$142,MATCH(B19,'Rule Matrix'!$A$2:$A$142,0))) -> B. ITC Eligibility (s.16) | D19: =IF(B19="","",INDEX('Rule Matrix'!$C$2:$C$142,MATCH(B19,'Rule Matrix'!$A$2:$A$142,0))) -> ITC on invoices from cancelled/composition vendors | E19: =IF(B19="","",INDEX('Rule Matrix'!$D$2:$D$142,MATCH(B19,'Rule Matrix'!$A$2:$A$142,0))) -> s.16, s.10(4) | F19: =IF(B19="","",INDEX('Rule Matrix'!$F$2:$F$142,MATCH(B19,'Rule Matrix'!$A$2:$A$142,0))) -> Tax charged by composition dealer or post-cancellation invoice | G19: =IF(B19="","",INDEX('Rule Matrix'!$G$2:$G$142,MATCH(B19,'Rule Matrix'!$A$2:$A$142,0))) -> Any | H19: =IF(B19="","",INDEX('Rule Matrix'!$H$2:$H$142,MATCH(B19,'Rule Matrix'!$A$2:$A$142,0))) -> High | I19: =IF(B19="","",INDEX('Rule Matrix'!$J$2:$J$142,MATCH(B19,'Rule Matrix'!$A$2:$A$142,0))) -> Reverse | Z19: =Applicability!A13 -> B-09 | AA19: =IF($Z$5=0,0,IF(AND(INDEX(Applicability!$E$13:$O$13,1,$Z$5)="Y",OR(Applicability!$D$13="",IFERROR(INDEX($B$4:$F$4,MATCH(Applicability!$D$13,$B$3:$F$3,0)),"N")="Y")),1,0)) -> 0 | AB19: =IF(AA19=1,SUM(AA$8:AA19),"")
A20: =IF(13>$B$5,"",13) -> 13 | B20: =IF(A20="","",INDEX($Z$8:$Z$148,MATCH(A20,$AB$8:$AB$148,0))) -> B-11 | C20: =IF(B20="","",INDEX('Rule Matrix'!$B$2:$B$142,MATCH(B20,'Rule Matrix'!$A$2:$A$142,0))) -> B. ITC Eligibility (s.16) | D20: =IF(B20="","",INDEX('Rule Matrix'!$C$2:$C$142,MATCH(B20,'Rule Matrix'!$A$2:$A$142,0))) -> Document validity | E20: =IF(B20="","",INDEX('Rule Matrix'!$D$2:$D$142,MATCH(B20,'Rule Matrix'!$A$2:$A$142,0))) -> s.16(2)(a), Rule 36 | F20: =IF(B20="","",INDEX('Rule Matrix'!$F$2:$F$142,MATCH(B20,'Rule Matrix'!$A$2:$A$142,0))) -> Mandatory particulars present (Rule 46): GSTIN, HSN, POS, tax break-up; e-invoice IRN where supplier mandated | G20: =IF(B20="","",INDEX('Rule Matrix'!$G$2:$G$142,MATCH(B20,'Rule Matrix'!$A$2:$A$142,0))) -> Any | H20: =IF(B20="","",INDEX('Rule Matrix'!$H$2:$H$142,MATCH(B20,'Rule Matrix'!$A$2:$A$142,0))) -> Med | I20: =IF(B20="","",INDEX('Rule Matrix'!$J$2:$J$142,MATCH(B20,'Rule Matrix'!$A$2:$A$142,0))) -> Obtain corrected invoice | Z20: =Applicability!A14 -> B-10 | AA20: =IF($Z$5=0,0,IF(AND(INDEX(Applicability!$E$14:$O$14,1,$Z$5)="Y",OR(Applicability!$D$14="",IFERROR(INDEX($B$4:$F$4,MATCH(Applicability!$D$14,$B$3:$F$3,0)),"N")="Y")),1,0)) -> 1 | AB20: =IF(AA20=1,SUM(AA$8:AA20),"") -> 12
A21: =IF(14>$B$5,"",14) -> 14 | B21: =IF(A21="","",INDEX($Z$8:$Z$148,MATCH(A21,$AB$8:$AB$148,0))) -> C-01 | C21: =IF(B21="","",INDEX('Rule Matrix'!$B$2:$B$142,MATCH(B21,'Rule Matrix'!$A$2:$A$142,0))) -> C. RCM | D21: =IF(B21="","",INDEX('Rule Matrix'!$C$2:$C$142,MATCH(B21,'Rule Matrix'!$A$2:$A$142,0))) -> RCM liability identification | E21: =IF(B21="","",INDEX('Rule Matrix'!$D$2:$D$142,MATCH(B21,'Rule Matrix'!$A$2:$A$142,0))) -> s.9(3), 9(4); Notfn 13/2017-CT(R) | F21: =IF(B21="","",INDEX('Rule Matrix'!$F$2:$F$142,MATCH(B21,'Rule Matrix'!$A$2:$A$142,0))) -> Map GTA, legal, security, director sitting fees, sponsorship, renting by URP, import of services; compute liability | G21: =IF(B21="","",INDEX('Rule Matrix'!$G$2:$G$142,MATCH(B21,'Rule Matrix'!$A$2:$A$142,0))) -> Any unpaid | H21: =IF(B21="","",INDEX('Rule Matrix'!$H$2:$H$142,MATCH(B21,'Rule Matrix'!$A$2:$A$142,0))) -> High | I21: =IF(B21="","",INDEX('Rule Matrix'!$J$2:$J$142,MATCH(B21,'Rule Matrix'!$A$2:$A$142,0))) -> Pay via cash ledger; claim ITC | Z21: =Applicability!A15 -> B-11 | AA21: =IF($Z$5=0,0,IF(AND(INDEX(Applicability!$E$15:$O$15,1,$Z$5)="Y",OR(Applicability!$D$15="",IFERROR(INDEX($B$4:$F$4,MATCH(Applicability!$D$15,$B$3:$F$3,0)),"N")="Y")),1,0)) -> 1 | AB21: =IF(AA21=1,SUM(AA$8:AA21),"") -> 13
A22: =IF(15>$B$5,"",15) -> 15 | B22: =IF(A22="","",INDEX($Z$8:$Z$148,MATCH(A22,$AB$8:$AB$148,0))) -> C-02 | C22: =IF(B22="","",INDEX('Rule Matrix'!$B$2:$B$142,MATCH(B22,'Rule Matrix'!$A$2:$A$142,0))) -> C. RCM | D22: =IF(B22="","",INDEX('Rule Matrix'!$C$2:$C$142,MATCH(B22,'Rule Matrix'!$A$2:$A$142,0))) -> RCM ITC after payment | E22: =IF(B22="","",INDEX('Rule Matrix'!$D$2:$D$142,MATCH(B22,'Rule Matrix'!$A$2:$A$142,0))) -> s.16, Rule 36(1)(b) | F22: =IF(B22="","",INDEX('Rule Matrix'!$F$2:$F$142,MATCH(B22,'Rule Matrix'!$A$2:$A$142,0))) -> ITC on RCM ≤ RCM tax paid in cash in same/earlier period | G22: =IF(B22="","",INDEX('Rule Matrix'!$G$2:$G$142,MATCH(B22,'Rule Matrix'!$A$2:$A$142,0))) -> ITC > paid | H22: =IF(B22="","",INDEX('Rule Matrix'!$H$2:$H$142,MATCH(B22,'Rule Matrix'!$A$2:$A$142,0))) -> High | I22: =IF(B22="","",INDEX('Rule Matrix'!$J$2:$J$142,MATCH(B22,'Rule Matrix'!$A$2:$A$142,0))) -> Reverse | Z22: =Applicability!A16 -> C-01 | AA22: =IF($Z$5=0,0,IF(AND(INDEX(Applicability!$E$16:$O$16,1,$Z$5)="Y",OR(Applicability!$D$16="",IFERROR(INDEX($B$4:$F$4,MATCH(Applicability!$D$16,$B$3:$F$3,0)),"N")="Y")),1,0)) -> 1 | AB22: =IF(AA22=1,SUM(AA$8:AA22),"") -> 14
A23: =IF(16>$B$5,"",16) -> 16 | B23: =IF(A23="","",INDEX($Z$8:$Z$148,MATCH(A23,$AB$8:$AB$148,0))) -> C-03 | C23: =IF(B23="","",INDEX('Rule Matrix'!$B$2:$B$142,MATCH(B23,'Rule Matrix'!$A$2:$A$142,0))) -> C. RCM | D23: =IF(B23="","",INDEX('Rule Matrix'!$C$2:$C$142,MATCH(B23,'Rule Matrix'!$A$2:$A$142,0))) -> RCM self-invoice | E23: =IF(B23="","",INDEX('Rule Matrix'!$D$2:$D$142,MATCH(B23,'Rule Matrix'!$A$2:$A$142,0))) -> s.31(3)(f), Rule 47A | F23: =IF(B23="","",INDEX('Rule Matrix'!$F$2:$F$142,MATCH(B23,'Rule Matrix'!$A$2:$A$142,0))) -> Self-invoice issued within 30 days of receipt of supply | G23: =IF(B23="","",INDEX('Rule Matrix'!$G$2:$G$142,MATCH(B23,'Rule Matrix'!$A$2:$A$142,0))) -> Delay | H23: =IF(B23="","",INDEX('Rule Matrix'!$H$2:$H$142,MATCH(B23,'Rule Matrix'!$A$2:$A$142,0))) -> Low | I23: =IF(B23="","",INDEX('Rule Matrix'!$J$2:$J$142,MATCH(B23,'Rule Matrix'!$A$2:$A$142,0))) -> Issue self-invoices | Z23: =Applicability!A17 -> C-02 | AA23: =IF($Z$5=0,0,IF(AND(INDEX(Applicability!$E$17:$O$17,1,$Z$5)="Y",OR(Applicability!$D$17="",IFERROR(INDEX($B$4:$F$4,MATCH(Applicability!$D$17,$B$3:$F$3,0)),"N")="Y")),1,0)) -> 1 | AB23: =IF(AA23=1,SUM(AA$8:AA23),"") -> 15
A24: =IF(17>$B$5,"",17) -> 17 | B24: =IF(A24="","",INDEX($Z$8:$Z$148,MATCH(A24,$AB$8:$AB$148,0))) -> D-01 | C24: =IF(B24="","",INDEX('Rule Matrix'!$B$2:$B$142,MATCH(B24,'Rule Matrix'!$A$2:$A$142,0))) -> D. Place of Supply | D24: =IF(B24="","",INDEX('Rule Matrix'!$C$2:$C$142,MATCH(B24,'Rule Matrix'!$A$2:$A$142,0))) -> Tax head vs state codes | E24: =IF(B24="","",INDEX('Rule Matrix'!$D$2:$D$142,MATCH(B24,'Rule Matrix'!$A$2:$A$142,0))) -> IGST s.7, 8 | F24: =IF(B24="","",INDEX('Rule Matrix'!$F$2:$F$142,MATCH(B24,'Rule Matrix'!$A$2:$A$142,0))) -> Supplier state ≠ POS → IGST; same → CGST+SGST; mismatch flagged | G24: =IF(B24="","",INDEX('Rule Matrix'!$G$2:$G$142,MATCH(B24,'Rule Matrix'!$A$2:$A$142,0))) -> Any | H24: =IF(B24="","",INDEX('Rule Matrix'!$H$2:$H$142,MATCH(B24,'Rule Matrix'!$A$2:$A$142,0))) -> High | I24: =IF(B24="","",INDEX('Rule Matrix'!$J$2:$J$142,MATCH(B24,'Rule Matrix'!$A$2:$A$142,0))) -> s.77 / Rule 89 refund route; correct invoices | Z24: =Applicability!A18 -> C-03 | AA24: =IF($Z$5=0,0,IF(AND(INDEX(Applicability!$E$18:$O$18,1,$Z$5)="Y",OR(Applicability!$D$18="",IFERROR(INDEX($B$4:$F$4,MATCH(Applicability!$D$18,$B$3:$F$3,0)),"N")="Y")),1,0)) -> 1 | AB24: =IF(AA24=1,SUM(AA$8:AA24),"") -> 16
A25: =IF(18>$B$5,"",18) -> 18 | B25: =IF(A25="","",INDEX($Z$8:$Z$148,MATCH(A25,$AB$8:$AB$148,0))) -> D-02 | C25: =IF(B25="","",INDEX('Rule Matrix'!$B$2:$B$142,MATCH(B25,'Rule Matrix'!$A$2:$A$142,0))) -> D. Place of Supply | D25: =IF(B25="","",INDEX('Rule Matrix'!$C$2:$C$142,MATCH(B25,'Rule Matrix'!$A$2:$A$142,0))) -> Hotel/immovable property services | E25: =IF(B25="","",INDEX('Rule Matrix'!$D$2:$D$142,MATCH(B25,'Rule Matrix'!$A$2:$A$142,0))) -> IGST s.12(3) | F25: =IF(B25="","",INDEX('Rule Matrix'!$F$2:$F$142,MATCH(B25,'Rule Matrix'!$A$2:$A$142,0))) -> POS = location of property; out-of-state CGST/SGST → ITC not available to recipient | G25: =IF(B25="","",INDEX('Rule Matrix'!$G$2:$G$142,MATCH(B25,'Rule Matrix'!$A$2:$A$142,0))) -> Any | H25: =IF(B25="","",INDEX('Rule Matrix'!$H$2:$H$142,MATCH(B25,'Rule Matrix'!$A$2:$A$142,0))) -> Med | I25: =IF(B25="","",INDEX('Rule Matrix'!$J$2:$J$142,MATCH(B25,'Rule Matrix'!$A$2:$A$142,0))) -> Reverse; register in that state if recurring | Z25: =Applicability!A19 -> C-04 | AA25: =IF($Z$5=0,0,IF(AND(INDEX(Applicability!$E$19:$O$19,1,$Z$5)="Y",OR(Applicability!$D$19="",IFERROR(INDEX($B$4:$F$4,MATCH(Applicability!$D$19,$B$3:$F$3,0)),"N")="Y")),1,0)) -> 0 | AB25: =IF(AA25=1,SUM(AA$8:AA25),"")
A26: =IF(19>$B$5,"",19) -> 19 | B26: =IF(A26="","",INDEX($Z$8:$Z$148,MATCH(A26,$AB$8:$AB$148,0))) -> D-03 | C26: =IF(B26="","",INDEX('Rule Matrix'!$B$2:$B$142,MATCH(B26,'Rule Matrix'!$A$2:$A$142,0))) -> D. Place of Supply | D26: =IF(B26="","",INDEX('Rule Matrix'!$C$2:$C$142,MATCH(B26,'Rule Matrix'!$A$2:$A$142,0))) -> Restaurant/catering, training, events | E26: =IF(B26="","",INDEX('Rule Matrix'!$D$2:$D$142,MATCH(B26,'Rule Matrix'!$A$2:$A$142,0))) -> IGST s.12(4)(5)(7) | F26: =IF(B26="","",INDEX('Rule Matrix'!$F$2:$F$142,MATCH(B26,'Rule Matrix'!$A$2:$A$142,0))) -> Services performed in other state with other state CGST/SGST | G26: =IF(B26="","",INDEX('Rule Matrix'!$G$2:$G$142,MATCH(B26,'Rule Matrix'!$A$2:$A$142,0))) -> Any | H26: =IF(B26="","",INDEX('Rule Matrix'!$H$2:$H$142,MATCH(B26,'Rule Matrix'!$A$2:$A$142,0))) -> Med | I26: =IF(B26="","",INDEX('Rule Matrix'!$J$2:$J$142,MATCH(B26,'Rule Matrix'!$A$2:$A$142,0))) -> Reverse | Z26: =Applicability!A20 -> C-05 | AA26: =IF($Z$5=0,0,IF(AND(INDEX(Applicability!$E$20:$O$20,1,$Z$5)="Y",OR(Applicability!$D$20="",IFERROR(INDEX($B$4:$F$4,MATCH(Applicability!$D$20,$B$3:$F$3,0)),"N")="Y")),1,0)) -> 0 | AB26: =IF(AA26=1,SUM(AA$8:AA26),"")
A27: =IF(20>$B$5,"",20) -> 20 | B27: =IF(A27="","",INDEX($Z$8:$Z$148,MATCH(A27,$AB$8:$AB$148,0))) -> D-04 | C27: =IF(B27="","",INDEX('Rule Matrix'!$B$2:$B$142,MATCH(B27,'Rule Matrix'!$A$2:$A$142,0))) -> D. Place of Supply | D27: =IF(B27="","",INDEX('Rule Matrix'!$C$2:$C$142,MATCH(B27,'Rule Matrix'!$A$2:$A$142,0))) -> Goods transport / passenger transport | E27: =IF(B27="","",INDEX('Rule Matrix'!$D$2:$D$142,MATCH(B27,'Rule Matrix'!$A$2:$A$142,0))) -> IGST s.12(8)(9) | F27: =IF(B27="","",INDEX('Rule Matrix'!$F$2:$F$142,MATCH(B27,'Rule Matrix'!$A$2:$A$142,0))) -> POS per recipient location (registered) / boarding point; head consistency | G27: =IF(B27="","",INDEX('Rule Matrix'!$G$2:$G$142,MATCH(B27,'Rule Matrix'!$A$2:$A$142,0))) -> Any | H27: =IF(B27="","",INDEX('Rule Matrix'!$H$2:$H$142,MATCH(B27,'Rule Matrix'!$A$2:$A$142,0))) -> Low | I27: =IF(B27="","",INDEX('Rule Matrix'!$J$2:$J$142,MATCH(B27,'Rule Matrix'!$A$2:$A$142,0))) -> Correct | Z27: =Applicability!A21 -> D-01 | AA27: =IF($Z$5=0,0,IF(AND(INDEX(Applicability!$E$21:$O$21,1,$Z$5)="Y",OR(Applicability!$D$21="",IFERROR(INDEX($B$4:$F$4,MATCH(Applicability!$D$21,$B$3:$F$3,0)),"N")="Y")),1,0)) -> 1 | AB27: =IF(AA27=1,SUM(AA$8:AA27),"") -> 17
A28: =IF(21>$B$5,"",21) -> 21 | B28: =IF(A28="","",INDEX($Z$8:$Z$148,MATCH(A28,$AB$8:$AB$148,0))) -> D-05 | C28: =IF(B28="","",INDEX('Rule Matrix'!$B$2:$B$142,MATCH(B28,'Rule Matrix'!$A$2:$A$142,0))) -> D. Place of Supply | D28: =IF(B28="","",INDEX('Rule Matrix'!$C$2:$C$142,MATCH(B28,'Rule Matrix'!$A$2:$A$142,0))) -> Bill-to-ship-to goods | E28: =IF(B28="","",INDEX('Rule Matrix'!$D$2:$D$142,MATCH(B28,'Rule Matrix'!$A$2:$A$142,0))) -> IGST s.10(1)(b) | F28: =IF(B28="","",INDEX('Rule Matrix'!$F$2:$F$142,MATCH(B28,'Rule Matrix'!$A$2:$A$142,0))) -> POS = principal place of 'bill-to' party; verify tax head | G28: =IF(B28="","",INDEX('Rule Matrix'!$G$2:$G$142,MATCH(B28,'Rule Matrix'!$A$2:$A$142,0))) -> Any | H28: =IF(B28="","",INDEX('Rule Matrix'!$H$2:$H$142,MATCH(B28,'Rule Matrix'!$A$2:$A$142,0))) -> Med | I28: =IF(B28="","",INDEX('Rule Matrix'!$J$2:$J$142,MATCH(B28,'Rule Matrix'!$A$2:$A$142,0))) -> Correct | Z28: =Applicability!A22 -> D-02 | AA28: =IF($Z$5=0,0,IF(AND(INDEX(Applicability!$E$22:$O$22,1,$Z$5)="Y",OR(Applicability!$D$22="",IFERROR(INDEX($B$4:$F$4,MATCH(Applicability!$D$22,$B$3:$F$3,0)),"N")="Y")),1,0)) -> 1 | AB28: =IF(AA28=1,SUM(AA$8:AA28),"") -> 18
A29: =IF(22>$B$5,"",22) -> 22 | B29: =IF(A29="","",INDEX($Z$8:$Z$148,MATCH(A29,$AB$8:$AB$148,0))) -> D-06 | C29: =IF(B29="","",INDEX('Rule Matrix'!$B$2:$B$142,MATCH(B29,'Rule Matrix'!$A$2:$A$142,0))) -> D. Place of Supply | D29: =IF(B29="","",INDEX('Rule Matrix'!$C$2:$C$142,MATCH(B29,'Rule Matrix'!$A$2:$A$142,0))) -> B2C recipient address | E29: =IF(B29="","",INDEX('Rule Matrix'!$D$2:$D$142,MATCH(B29,'Rule Matrix'!$A$2:$A$142,0))) -> IGST s.10(1)(ca) | F29: =IF(B29="","",INDEX('Rule Matrix'!$F$2:$F$142,MATCH(B29,'Rule Matrix'!$A$2:$A$142,0))) -> B2C inter-state: recipient state recorded; else POS = supplier location | G29: =IF(B29="","",INDEX('Rule Matrix'!$G$2:$G$142,MATCH(B29,'Rule Matrix'!$A$2:$A$142,0))) -> Missing | H29: =IF(B29="","",INDEX('Rule Matrix'!$H$2:$H$142,MATCH(B29,'Rule Matrix'!$A$2:$A$142,0))) -> Low | I29: =IF(B29="","",INDEX('Rule Matrix'!$J$2:$J$142,MATCH(B29,'Rule Matrix'!$A$2:$A$142,0))) -> Capture address | Z29: =Applicability!A23 -> D-03 | AA29: =IF($Z$5=0,0,IF(AND(INDEX(Applicability!$E$23:$O$23,1,$Z$5)="Y",OR(Applicability!$D$23="",IFERROR(INDEX($B$4:$F$4,MATCH(Applicability!$D$23,$B$3:$F$3,0)),"N")="Y")),1,0)) -> 1 | AB29: =IF(AA29=1,SUM(AA$8:AA29),"") -> 19
A30: =IF(23>$B$5,"",23) -> 23 | B30: =IF(A30="","",INDEX($Z$8:$Z$148,MATCH(A30,$AB$8:$AB$148,0))) -> E-01 | C30: =IF(B30="","",INDEX('Rule Matrix'!$B$2:$B$142,MATCH(B30,'Rule Matrix'!$A$2:$A$142,0))) -> E. Blocked Credits s.17(5) | D30: =IF(B30="","",INDEX('Rule Matrix'!$C$2:$C$142,MATCH(B30,'Rule Matrix'!$A$2:$A$142,0))) -> Motor vehicles ≤13 seats | E30: =IF(B30="","",INDEX('Rule Matrix'!$D$2:$D$142,MATCH(B30,'Rule Matrix'!$A$2:$A$142,0))) -> s.17(5)(a),(ab) | F30: =IF(B30="","",INDEX('Rule Matrix'!$F$2:$F$142,MATCH(B30,'Rule Matrix'!$A$2:$A$142,0))) -> ITC on cars and their repairs/insurance unless used for further supply, passenger transport, driving training | G30: =IF(B30="","",INDEX('Rule Matrix'!$G$2:$G$142,MATCH(B30,'Rule Matrix'!$A$2:$A$142,0))) -> Any | H30: =IF(B30="","",INDEX('Rule Matrix'!$H$2:$H$142,MATCH(B30,'Rule Matrix'!$A$2:$A$142,0))) -> High | I30: =IF(B30="","",INDEX('Rule Matrix'!$J$2:$J$142,MATCH(B30,'Rule Matrix'!$A$2:$A$142,0))) -> Reverse | Z30: =Applicability!A24 -> D-04 | AA30: =IF($Z$5=0,0,IF(AND(INDEX(Applicability!$E$24:$O$24,1,$Z$5)="Y",OR(Applicability!$D$24="",IFERROR(INDEX($B$4:$F$4,MATCH(Applicability!$D$24,$B$3:$F$3,0)),"N")="Y")),1,0)) -> 1 | AB30: =IF(AA30=1,SUM(AA$8:AA30),"") -> 20
A31: =IF(24>$B$5,"",24) -> 24 | B31: =IF(A31="","",INDEX($Z$8:$Z$148,MATCH(A31,$AB$8:$AB$148,0))) -> E-02 | C31: =IF(B31="","",INDEX('Rule Matrix'!$B$2:$B$142,MATCH(B31,'Rule Matrix'!$A$2:$A$142,0))) -> E. Blocked Credits s.17(5) | D31: =IF(B31="","",INDEX('Rule Matrix'!$C$2:$C$142,MATCH(B31,'Rule Matrix'!$A$2:$A$142,0))) -> Vessels & aircraft | E31: =IF(B31="","",INDEX('Rule Matrix'!$D$2:$D$142,MATCH(B31,'Rule Matrix'!$A$2:$A$142,0))) -> s.17(5)(aa),(ab) | F31: =IF(B31="","",INDEX('Rule Matrix'!$F$2:$F$142,MATCH(B31,'Rule Matrix'!$A$2:$A$142,0))) -> ITC except permitted uses | G31: =IF(B31="","",INDEX('Rule Matrix'!$G$2:$G$142,MATCH(B31,'Rule Matrix'!$A$2:$A$142,0))) -> Any | H31: =IF(B31="","",INDEX('Rule Matrix'!$H$2:$H$142,MATCH(B31,'Rule Matrix'!$A$2:$A$142,0))) -> High | I31: =IF(B31="","",INDEX('Rule Matrix'!$J$2:$J$142,MATCH(B31,'Rule Matrix'!$A$2:$A$142,0))) -> Reverse | Z31: =Applicability!A25 -> D-05 | AA31: =IF($Z$5=0,0,IF(AND(INDEX(Applicability!$E$25:$O$25,1,$Z$5)="Y",OR(Applicability!$D$25="",IFERROR(INDEX($B$4:$F$4,MATCH(Applicability!$D$25,$B$3:$F$3,0)),"N")="Y")),1,0)) -> 1 | AB31: =IF(AA31=1,SUM(AA$8:AA31),"") -> 21
A32: =IF(25>$B$5,"",25) -> 25 | B32: =IF(A32="","",INDEX($Z$8:$Z$148,MATCH(A32,$AB$8:$AB$148,0))) -> E-03 | C32: =IF(B32="","",INDEX('Rule Matrix'!$B$2:$B$142,MATCH(B32,'Rule Matrix'!$A$2:$A$142,0))) -> E. Blocked Credits s.17(5) | D32: =IF(B32="","",INDEX('Rule Matrix'!$C$2:$C$142,MATCH(B32,'Rule Matrix'!$A$2:$A$142,0))) -> Food, beverages, outdoor catering | E32: =IF(B32="","",INDEX('Rule Matrix'!$D$2:$D$142,MATCH(B32,'Rule Matrix'!$A$2:$A$142,0))) -> s.17(5)(b)(i) | F32: =IF(B32="","",INDEX('Rule Matrix'!$F$2:$F$142,MATCH(B32,'Rule Matrix'!$A$2:$A$142,0))) -> ITC unless obligatory under law or same line of outward supply | G32: =IF(B32="","",INDEX('Rule Matrix'!$G$2:$G$142,MATCH(B32,'Rule Matrix'!$A$2:$A$142,0))) -> Any | H32: =IF(B32="","",INDEX('Rule Matrix'!$H$2:$H$142,MATCH(B32,'Rule Matrix'!$A$2:$A$142,0))) -> High | I32: =IF(B32="","",INDEX('Rule Matrix'!$J$2:$J$142,MATCH(B32,'Rule Matrix'!$A$2:$A$142,0))) -> Reverse | Z32: =Applicability!A26 -> D-06 | AA32: =IF($Z$5=0,0,IF(AND(INDEX(Applicability!$E$26:$O$26,1,$Z$5)="Y",OR(Applicability!$D$26="",IFERROR(INDEX($B$4:$F$4,MATCH(Applicability!$D$26,$B$3:$F$3,0)),"N")="Y")),1,0)) -> 1 | AB32: =IF(AA32=1,SUM(AA$8:AA32),"") -> 22
A33: =IF(26>$B$5,"",26) -> 26 | B33: =IF(A33="","",INDEX($Z$8:$Z$148,MATCH(A33,$AB$8:$AB$148,0))) -> E-04 | C33: =IF(B33="","",INDEX('Rule Matrix'!$B$2:$B$142,MATCH(B33,'Rule Matrix'!$A$2:$A$142,0))) -> E. Blocked Credits s.17(5) | D33: =IF(B33="","",INDEX('Rule Matrix'!$C$2:$C$142,MATCH(B33,'Rule Matrix'!$A$2:$A$142,0))) -> Beauty, health, cosmetic surgery | E33: =IF(B33="","",INDEX('Rule Matrix'!$D$2:$D$142,MATCH(B33,'Rule Matrix'!$A$2:$A$142,0))) -> s.17(5)(b)(i) | F33: =IF(B33="","",INDEX('Rule Matrix'!$F$2:$F$142,MATCH(B33,'Rule Matrix'!$A$2:$A$142,0))) -> Blocked unless same line of outward supply. Note: beauty/wellness now 5% without ITC w.e.f. 22.09.2025 (Notfn 15/2025-CT(R)) | G33: =IF(B33="","",INDEX('Rule Matrix'!$G$2:$G$142,MATCH(B33,'Rule Matrix'!$A$2:$A$142,0))) -> Any | H33: =IF(B33="","",INDEX('Rule Matrix'!$H$2:$H$142,MATCH(B33,'Rule Matrix'!$A$2:$A$142,0))) -> Med | I33: =IF(B33="","",INDEX('Rule Matrix'!$J$2:$J$142,MATCH(B33,'Rule Matrix'!$A$2:$A$142,0))) -> Reverse | Z33: =Applicability!A27 -> D-07 | AA33: =IF($Z$5=0,0,IF(AND(INDEX(Applicability!$E$27:$O$27,1,$Z$5)="Y",OR(Applicability!$D$27="",IFERROR(INDEX($B$4:$F$4,MATCH(Applicability!$D$27,$B$3:$F$3,0)),"N")="Y")),1,0)) -> 0 | AB33: =IF(AA33=1,SUM(AA$8:AA33),"")
A34: =IF(27>$B$5,"",27) -> 27 | B34: =IF(A34="","",INDEX($Z$8:$Z$148,MATCH(A34,$AB$8:$AB$148,0))) -> E-05 | C34: =IF(B34="","",INDEX('Rule Matrix'!$B$2:$B$142,MATCH(B34,'Rule Matrix'!$A$2:$A$142,0))) -> E. Blocked Credits s.17(5) | D34: =IF(B34="","",INDEX('Rule Matrix'!$C$2:$C$142,MATCH(B34,'Rule Matrix'!$A$2:$A$142,0))) -> Life & health insurance | E34: =IF(B34="","",INDEX('Rule Matrix'!$D$2:$D$142,MATCH(B34,'Rule Matrix'!$A$2:$A$142,0))) -> s.17(5)(b)(i) | F34: =IF(B34="","",INDEX('Rule Matrix'!$F$2:$F$142,MATCH(B34,'Rule Matrix'!$A$2:$A$142,0))) -> Individual life & health policies exempt w.e.f. 22.09.2025 (no ITC issue). Group / employer policies: ITC blocked unless obligatory under law (s.17(5)(b) proviso) | G34: =IF(B34="","",INDEX('Rule Matrix'!$G$2:$G$142,MATCH(B34,'Rule Matrix'!$A$2:$A$142,0))) -> Any | H34: =IF(B34="","",INDEX('Rule Matrix'!$H$2:$H$142,MATCH(B34,'Rule Matrix'!$A$2:$A$142,0))) -> Med | I34: =IF(B34="","",INDEX('Rule Matrix'!$J$2:$J$142,MATCH(B34,'Rule Matrix'!$A$2:$A$142,0))) -> Reverse | Z34: =Applicability!A28 -> D-08 | AA34: =IF($Z$5=0,0,IF(AND(INDEX(Applicability!$E$28:$O$28,1,$Z$5)="Y",OR(Applicability!$D$28="",IFERROR(INDEX($B$4:$F$4,MATCH(Applicability!$D$28,$B$3:$F$3,0)),"N")="Y")),1,0)) -> 0 | AB34: =IF(AA34=1,SUM(AA$8:AA34),"")
A35: =IF(28>$B$5,"",28) -> 28 | B35: =IF(A35="","",INDEX($Z$8:$Z$148,MATCH(A35,$AB$8:$AB$148,0))) -> E-06 | C35: =IF(B35="","",INDEX('Rule Matrix'!$B$2:$B$142,MATCH(B35,'Rule Matrix'!$A$2:$A$142,0))) -> E. Blocked Credits s.17(5) | D35: =IF(B35="","",INDEX('Rule Matrix'!$C$2:$C$142,MATCH(B35,'Rule Matrix'!$A$2:$A$142,0))) -> Club / fitness membership | E35: =IF(B35="","",INDEX('Rule Matrix'!$D$2:$D$142,MATCH(B35,'Rule Matrix'!$A$2:$A$142,0))) -> s.17(5)(b)(ii) | F35: =IF(B35="","",INDEX('Rule Matrix'!$F$2:$F$142,MATCH(B35,'Rule Matrix'!$A$2:$A$142,0))) -> Any ITC | G35: =IF(B35="","",INDEX('Rule Matrix'!$G$2:$G$142,MATCH(B35,'Rule Matrix'!$A$2:$A$142,0))) -> Any | H35: =IF(B35="","",INDEX('Rule Matrix'!$H$2:$H$142,MATCH(B35,'Rule Matrix'!$A$2:$A$142,0))) -> Med | I35: =IF(B35="","",INDEX('Rule Matrix'!$J$2:$J$142,MATCH(B35,'Rule Matrix'!$A$2:$A$142,0))) -> Reverse | Z35: =Applicability!A29 -> E-01 | AA35: =IF($Z$5=0,0,IF(AND(INDEX(Applicability!$E$29:$O$29,1,$Z$5)="Y",OR(Applicability!$D$29="",IFERROR(INDEX($B$4:$F$4,MATCH(Applicability!$D$29,$B$3:$F$3,0)),"N")="Y")),1,0)) -> 1 | AB35: =IF(AA35=1,SUM(AA$8:AA35),"") -> 23
A36: =IF(29>$B$5,"",29) -> 29 | B36: =IF(A36="","",INDEX($Z$8:$Z$148,MATCH(A36,$AB$8:$AB$148,0))) -> E-07 | C36: =IF(B36="","",INDEX('Rule Matrix'!$B$2:$B$142,MATCH(B36,'Rule Matrix'!$A$2:$A$142,0))) -> E. Blocked Credits s.17(5) | D36: =IF(B36="","",INDEX('Rule Matrix'!$C$2:$C$142,MATCH(B36,'Rule Matrix'!$A$2:$A$142,0))) -> Rent-a-cab | E36: =IF(B36="","",INDEX('Rule Matrix'!$D$2:$D$142,MATCH(B36,'Rule Matrix'!$A$2:$A$142,0))) -> s.17(5)(b)(i) | F36: =IF(B36="","",INDEX('Rule Matrix'!$F$2:$F$142,MATCH(B36,'Rule Matrix'!$A$2:$A$142,0))) -> Cab hire ITC unless obligatory / same outward supply | G36: =IF(B36="","",INDEX('Rule Matrix'!$G$2:$G$142,MATCH(B36,'Rule Matrix'!$A$2:$A$142,0))) -> Any | H36: =IF(B36="","",INDEX('Rule Matrix'!$H$2:$H$142,MATCH(B36,'Rule Matrix'!$A$2:$A$142,0))) -> Med | I36: =IF(B36="","",INDEX('Rule Matrix'!$J$2:$J$142,MATCH(B36,'Rule Matrix'!$A$2:$A$142,0))) -> Reverse | Z36: =Applicability!A30 -> E-02 | AA36: =IF($Z$5=0,0,IF(AND(INDEX(Applicability!$E$30:$O$30,1,$Z$5)="Y",OR(Applicability!$D$30="",IFERROR(INDEX($B$4:$F$4,MATCH(Applicability!$D$30,$B$3:$F$3,0)),"N")="Y")),1,0)) -> 1 | AB36: =IF(AA36=1,SUM(AA$8:AA36),"") -> 24
A37: =IF(30>$B$5,"",30) -> 30 | B37: =IF(A37="","",INDEX($Z$8:$Z$148,MATCH(A37,$AB$8:$AB$148,0))) -> E-08 | C37: =IF(B37="","",INDEX('Rule Matrix'!$B$2:$B$142,MATCH(B37,'Rule Matrix'!$A$2:$A$142,0))) -> E. Blocked Credits s.17(5) | D37: =IF(B37="","",INDEX('Rule Matrix'!$C$2:$C$142,MATCH(B37,'Rule Matrix'!$A$2:$A$142,0))) -> Employee travel benefits (LTC/vacation) | E37: =IF(B37="","",INDEX('Rule Matrix'!$D$2:$D$142,MATCH(B37,'Rule Matrix'!$A$2:$A$142,0))) -> s.17(5)(b)(iii) | F37: =IF(B37="","",INDEX('Rule Matrix'!$F$2:$F$142,MATCH(B37,'Rule Matrix'!$A$2:$A$142,0))) -> Any ITC | G37: =IF(B37="","",INDEX('Rule Matrix'!$G$2:$G$142,MATCH(B37,'Rule Matrix'!$A$2:$A$142,0))) -> Any | H37: =IF(B37="","",INDEX('Rule Matrix'!$H$2:$H$142,MATCH(B37,'Rule Matrix'!$A$2:$A$142,0))) -> Med | I37: =IF(B37="","",INDEX('Rule Matrix'!$J$2:$J$142,MATCH(B37,'Rule Matrix'!$A$2:$A$142,0))) -> Reverse | Z37: =Applicability!A31 -> E-03 | AA37: =IF($Z$5=0,0,IF(AND(INDEX(Applicability!$E$31:$O$31,1,$Z$5)="Y",OR(Applicability!$D$31="",IFERROR(INDEX($B$4:$F$4,MATCH(Applicability!$D$31,$B$3:$F$3,0)),"N")="Y")),1,0)) -> 1 | AB37: =IF(AA37=1,SUM(AA$8:AA37),"") -> 25
A38: =IF(31>$B$5,"",31) -> 31 | B38: =IF(A38="","",INDEX($Z$8:$Z$148,MATCH(A38,$AB$8:$AB$148,0))) -> E-09 | C38: =IF(B38="","",INDEX('Rule Matrix'!$B$2:$B$142,MATCH(B38,'Rule Matrix'!$A$2:$A$142,0))) -> E. Blocked Credits s.17(5) | D38: =IF(B38="","",INDEX('Rule Matrix'!$C$2:$C$142,MATCH(B38,'Rule Matrix'!$A$2:$A$142,0))) -> Works contract – immovable property | E38: =IF(B38="","",INDEX('Rule Matrix'!$D$2:$D$142,MATCH(B38,'Rule Matrix'!$A$2:$A$142,0))) -> s.17(5)(c) | F38: =IF(B38="","",INDEX('Rule Matrix'!$F$2:$F$142,MATCH(B38,'Rule Matrix'!$A$2:$A$142,0))) -> ITC on works contract services for construction of immovable property (other than 'plant and machinery') blocked, except where it is input service for further supply of works contract | G38: =IF(B38="","",INDEX('Rule Matrix'!$G$2:$G$142,MATCH(B38,'Rule Matrix'!$A$2:$A$142,0))) -> Any | H38: =IF(B38="","",INDEX('Rule Matrix'!$H$2:$H$142,MATCH(B38,'Rule Matrix'!$A$2:$A$142,0))) -> High | I38: =IF(B38="","",INDEX('Rule Matrix'!$J$2:$J$142,MATCH(B38,'Rule Matrix'!$A$2:$A$142,0))) -> Reverse | Z38: =Applicability!A32 -> E-04 | AA38: =IF($Z$5=0,0,IF(AND(INDEX(Applicability!$E$32:$O$32,1,$Z$5)="Y",OR(Applicability!$D$32="",IFERROR(INDEX($B$4:$F$4,MATCH(Applicability!$D$32,$B$3:$F$3,0)),"N")="Y")),1,0)) -> 1 | AB38: =IF(AA38=1,SUM(AA$8:AA38),"") -> 26
A39: =IF(32>$B$5,"",32) -> 32 | B39: =IF(A39="","",INDEX($Z$8:$Z$148,MATCH(A39,$AB$8:$AB$148,0))) -> E-10 | C39: =IF(B39="","",INDEX('Rule Matrix'!$B$2:$B$142,MATCH(B39,'Rule Matrix'!$A$2:$A$142,0))) -> E. Blocked Credits s.17(5) | D39: =IF(B39="","",INDEX('Rule Matrix'!$C$2:$C$142,MATCH(B39,'Rule Matrix'!$A$2:$A$142,0))) -> Construction on own account | E39: =IF(B39="","",INDEX('Rule Matrix'!$D$2:$D$142,MATCH(B39,'Rule Matrix'!$A$2:$A$142,0))) -> s.17(5)(d); Expl. 2 inserted by FA 2025 (retro 01.07.2017) | F39: =IF(B39="","",INDEX('Rule Matrix'!$F$2:$F$142,MATCH(B39,'Rule Matrix'!$A$2:$A$142,0))) -> 'plant or machinery' substituted by 'plant and machinery' retrospectively from 01.07.2017 – overrides functionality test of Safari Retreats (SC, 03.10.2024). Flag building/civil ITC even where property is let out | G39: =IF(B39="","",INDEX('Rule Matrix'!$G$2:$G$142,MATCH(B39,'Rule Matrix'!$A$2:$A$142,0))) -> Any | H39: =IF(B39="","",INDEX('Rule Matrix'!$H$2:$H$142,MATCH(B39,'Rule Matrix'!$A$2:$A$142,0))) -> High | I39: =IF(B39="","",INDEX('Rule Matrix'!$J$2:$J$142,MATCH(B39,'Rule Matrix'!$A$2:$A$142,0))) -> Reverse | Z39: =Applicability!A33 -> E-05 | AA39: =IF($Z$5=0,0,IF(AND(INDEX(Applicability!$E$33:$O$33,1,$Z$5)="Y",OR(Applicability!$D$33="",IFERROR(INDEX($B$4:$F$4,MATCH(Applicability!$D$33,$B$3:$F$3,0)),"N")="Y")),1,0)) -> 1 | AB39: =IF(AA39=1,SUM(AA$8:AA39),"") -> 27
A40: =IF(33>$B$5,"",33) -> 33 | B40: =IF(A40="","",INDEX($Z$8:$Z$148,MATCH(A40,$AB$8:$AB$148,0))) -> E-11 | C40: =IF(B40="","",INDEX('Rule Matrix'!$B$2:$B$142,MATCH(B40,'Rule Matrix'!$A$2:$A$142,0))) -> E. Blocked Credits s.17(5) | D40: =IF(B40="","",INDEX('Rule Matrix'!$C$2:$C$142,MATCH(B40,'Rule Matrix'!$A$2:$A$142,0))) -> Composition tax / NRTP | E40: =IF(B40="","",INDEX('Rule Matrix'!$D$2:$D$142,MATCH(B40,'Rule Matrix'!$A$2:$A$142,0))) -> s.17(5)(e),(f) | F40: =IF(B40="","",INDEX('Rule Matrix'!$F$2:$F$142,MATCH(B40,'Rule Matrix'!$A$2:$A$142,0))) -> ITC on goods/services where tax paid under composition or by NRTP (except imports) | G40: =IF(B40="","",INDEX('Rule Matrix'!$G$2:$G$142,MATCH(B40,'Rule Matrix'!$A$2:$A$142,0))) -> Any | H40: =IF(B40="","",INDEX('Rule Matrix'!$H$2:$H$142,MATCH(B40,'Rule Matrix'!$A$2:$A$142,0))) -> Med | I40: =IF(B40="","",INDEX('Rule Matrix'!$J$2:$J$142,MATCH(B40,'Rule Matrix'!$A$2:$A$142,0))) -> Reverse | Z40: =Applicability!A34 -> E-06 | AA40: =IF($Z$5=0,0,IF(AND(INDEX(Applicability!$E$34:$O$34,1,$Z$5)="Y",OR(Applicability!$D$34="",IFERROR(INDEX($B$4:$F$4,MATCH(Applicability!$D$34,$B$3:$F$3,0)),"N")="Y")),1,0)) -> 1 | AB40: =IF(AA40=1,SUM(AA$8:AA40),"") -> 28
A41: =IF(34>$B$5,"",34) -> 34 | B41: =IF(A41="","",INDEX($Z$8:$Z$148,MATCH(A41,$AB$8:$AB$148,0))) -> E-12 | C41: =IF(B41="","",INDEX('Rule Matrix'!$B$2:$B$142,MATCH(B41,'Rule Matrix'!$A$2:$A$142,0))) -> E. Blocked Credits s.17(5) | D41: =IF(B41="","",INDEX('Rule Matrix'!$C$2:$C$142,MATCH(B41,'Rule Matrix'!$A$2:$A$142,0))) -> CSR expenditure | E41: =IF(B41="","",INDEX('Rule Matrix'!$D$2:$D$142,MATCH(B41,'Rule Matrix'!$A$2:$A$142,0))) -> s.17(5)(fa) | F41: =IF(B41="","",INDEX('Rule Matrix'!$F$2:$F$142,MATCH(B41,'Rule Matrix'!$A$2:$A$142,0))) -> ITC on CSR spend (from 1.10.2023) | G41: =IF(B41="","",INDEX('Rule Matrix'!$G$2:$G$142,MATCH(B41,'Rule Matrix'!$A$2:$A$142,0))) -> Any | H41: =IF(B41="","",INDEX('Rule Matrix'!$H$2:$H$142,MATCH(B41,'Rule Matrix'!$A$2:$A$142,0))) -> High | I41: =IF(B41="","",INDEX('Rule Matrix'!$J$2:$J$142,MATCH(B41,'Rule Matrix'!$A$2:$A$142,0))) -> Reverse | Z41: =Applicability!A35 -> E-07 | AA41: =IF($Z$5=0,0,IF(AND(INDEX(Applicability!$E$35:$O$35,1,$Z$5)="Y",OR(Applicability!$D$35="",IFERROR(INDEX($B$4:$F$4,MATCH(Applicability!$D$35,$B$3:$F$3,0)),"N")="Y")),1,0)) -> 1 | AB41: =IF(AA41=1,SUM(AA$8:AA41),"") -> 29
...

Sheet Summary
A1: Module | B1: Total | C1: High | D1: Med | E1: Low | F1: Fail | G1: Pending | H1: Exposure (₹)
A2: A. Data Integrity | B2: =COUNTIF('Rule Matrix'!$B$2:$B$142,A2) -> 3 | C2: =COUNTIFS('Rule Matrix'!$B$2:$B$142,A2,'Rule Matrix'!$H$2:$H$142,"High") -> 1 | D2: =COUNTIFS('Rule Matrix'!$B$2:$B$142,A2,'Rule Matrix'!$H$2:$H$142,"Med") -> 2 | E2: =COUNTIFS('Rule Matrix'!$B$2:$B$142,A2,'Rule Matrix'!$H$2:$H$142,"Low") -> 0 | F2: =COUNTIFS('Rule Matrix'!$B$2:$B$142,A2,'Rule Matrix'!$K$2:$K$142,"Fail") -> 1 | G2: =COUNTIFS('Rule Matrix'!$B$2:$B$142,A2,'Rule Matrix'!$K$2:$K$142,"Pending") -> 2 | H2: =SUMIFS('Rule Matrix'!$L$2:$L$142,'Rule Matrix'!$B$2:$B$142,A2) -> 125000
A3: B. ITC Eligibility (s.16) | B3: =COUNTIF('Rule Matrix'!$B$2:$B$142,A3) -> 11 | C3: =COUNTIFS('Rule Matrix'!$B$2:$B$142,A3,'Rule Matrix'!$H$2:$H$142,"High") -> 8 | D3: =COUNTIFS('Rule Matrix'!$B$2:$B$142,A3,'Rule Matrix'!$H$2:$H$142,"Med") -> 3 | E3: =COUNTIFS('Rule Matrix'!$B$2:$B$142,A3,'Rule Matrix'!$H$2:$H$142,"Low") -> 0 | F3: =COUNTIFS('Rule Matrix'!$B$2:$B$142,A3,'Rule Matrix'!$K$2:$K$142,"Fail") -> 0 | G3: =COUNTIFS('Rule Matrix'!$B$2:$B$142,A3,'Rule Matrix'!$K$2:$K$142,"Pending") -> 11 | H3: =SUMIFS('Rule Matrix'!$L$2:$L$142,'Rule Matrix'!$B$2:$B$142,A3) -> 0
A4: C. RCM | B4: =COUNTIF('Rule Matrix'!$B$2:$B$142,A4) -> 5 | C4: =COUNTIFS('Rule Matrix'!$B$2:$B$142,A4,'Rule Matrix'!$H$2:$H$142,"High") -> 3 | D4: =COUNTIFS('Rule Matrix'!$B$2:$B$142,A4,'Rule Matrix'!$H$2:$H$142,"Med") -> 1 | E4: =COUNTIFS('Rule Matrix'!$B$2:$B$142,A4,'Rule Matrix'!$H$2:$H$142,"Low") -> 1 | F4: =COUNTIFS('Rule Matrix'!$B$2:$B$142,A4,'Rule Matrix'!$K$2:$K$142,"Fail") -> 0 | G4: =COUNTIFS('Rule Matrix'!$B$2:$B$142,A4,'Rule Matrix'!$K$2:$K$142,"Pending") -> 5 | H4: =SUMIFS('Rule Matrix'!$L$2:$L$142,'Rule Matrix'!$B$2:$B$142,A4) -> 0
A5: D. Place of Supply | B5: =COUNTIF('Rule Matrix'!$B$2:$B$142,A5) -> 8 | C5: =COUNTIFS('Rule Matrix'!$B$2:$B$142,A5,'Rule Matrix'!$H$2:$H$142,"High") -> 2 | D5: =COUNTIFS('Rule Matrix'!$B$2:$B$142,A5,'Rule Matrix'!$H$2:$H$142,"Med") -> 4 | E5: =COUNTIFS('Rule Matrix'!$B$2:$B$142,A5,'Rule Matrix'!$H$2:$H$142,"Low") -> 2 | F5: =COUNTIFS('Rule Matrix'!$B$2:$B$142,A5,'Rule Matrix'!$K$2:$K$142,"Fail") -> 0 | G5: =COUNTIFS('Rule Matrix'!$B$2:$B$142,A5,'Rule Matrix'!$K$2:$K$142,"Pending") -> 8 | H5: =SUMIFS('Rule Matrix'!$L$2:$L$142,'Rule Matrix'!$B$2:$B$142,A5) -> 0
A6: E. Blocked Credits s.17(5) | B6: =COUNTIF('Rule Matrix'!$B$2:$B$142,A6) -> 15 | C6: =COUNTIFS('Rule Matrix'!$B$2:$B$142,A6,'Rule Matrix'!$H$2:$H$142,"High") -> 7 | D6: =COUNTIFS('Rule Matrix'!$B$2:$B$142,A6,'Rule Matrix'!$H$2:$H$142,"Med") -> 8 | E6: =COUNTIFS('Rule Matrix'!$B$2:$B$142,A6,'Rule Matrix'!$H$2:$H$142,"Low") -> 0 | F6: =COUNTIFS('Rule Matrix'!$B$2:$B$142,A6,'Rule Matrix'!$K$2:$K$142,"Fail") -> 0 | G6: =COUNTIFS('Rule Matrix'!$B$2:$B$142,A6,'Rule Matrix'!$K$2:$K$142,"Pending") -> 15 | H6: =SUMIFS('Rule Matrix'!$L$2:$L$142,'Rule Matrix'!$B$2:$B$142,A6) -> 0
A7: F. Reversals & Apportionment | B7: =COUNTIF('Rule Matrix'!$B$2:$B$142,A7) -> 7 | C7: =COUNTIFS('Rule Matrix'!$B$2:$B$142,A7,'Rule Matrix'!$H$2:$H$142,"High") -> 3 | D7: =COUNTIFS('Rule Matrix'!$B$2:$B$142,A7,'Rule Matrix'!$H$2:$H$142,"Med") -> 4 | E7: =COUNTIFS('Rule Matrix'!$B$2:$B$142,A7,'Rule Matrix'!$H$2:$H$142,"Low") -> 0 | F7: =COUNTIFS('Rule Matrix'!$B$2:$B$142,A7,'Rule Matrix'!$K$2:$K$142,"Fail") -> 0 | G7: =COUNTIFS('Rule Matrix'!$B$2:$B$142,A7,'Rule Matrix'!$K$2:$K$142,"Pending") -> 7 | H7: =SUMIFS('Rule Matrix'!$L$2:$L$142,'Rule Matrix'!$B$2:$B$142,A7) -> 0
A8: G. Outward Supplies | B8: =COUNTIF('Rule Matrix'!$B$2:$B$142,A8) -> 15 | C8: =COUNTIFS('Rule Matrix'!$B$2:$B$142,A8,'Rule Matrix'!$H$2:$H$142,"High") -> 8 | D8: =COUNTIFS('Rule Matrix'!$B$2:$B$142,A8,'Rule Matrix'!$H$2:$H$142,"Med") -> 6 | E8: =COUNTIFS('Rule Matrix'!$B$2:$B$142,A8,'Rule Matrix'!$H$2:$H$142,"Low") -> 1 | F8: =COUNTIFS('Rule Matrix'!$B$2:$B$142,A8,'Rule Matrix'!$K$2:$K$142,"Fail") -> 0 | G8: =COUNTIFS('Rule Matrix'!$B$2:$B$142,A8,'Rule Matrix'!$K$2:$K$142,"Pending") -> 15 | H8: =SUMIFS('Rule Matrix'!$L$2:$L$142,'Rule Matrix'!$B$2:$B$142,A8) -> 0
